[2025-01-29T23:45:11.342+0000] {taskinstance.py:1956} INFO - Dependencies all met for dep_context=non-requeueable deps ti=<TaskInstance: spotify_etl.load_task scheduled__2025-01-28T00:00:00+00:00 [queued]>
[2025-01-29T23:45:11.409+0000] {taskinstance.py:1956} INFO - Dependencies all met for dep_context=requeueable deps ti=<TaskInstance: spotify_etl.load_task scheduled__2025-01-28T00:00:00+00:00 [queued]>
[2025-01-29T23:45:11.424+0000] {taskinstance.py:2170} INFO - Starting attempt 2 of 2
[2025-01-29T23:45:11.536+0000] {taskinstance.py:2191} INFO - Executing <Task(PythonOperator): load_task> on 2025-01-28 00:00:00+00:00
[2025-01-29T23:45:11.590+0000] {standard_task_runner.py:60} INFO - Started process 188 to run task
[2025-01-29T23:45:11.677+0000] {standard_task_runner.py:87} INFO - Running: ['***', 'tasks', 'run', 'spotify_etl', 'load_task', 'scheduled__2025-01-28T00:00:00+00:00', '--job-id', '53', '--raw', '--subdir', 'DAGS_FOLDER/spotify_etl_dag.py', '--cfg-path', '/tmp/tmpkq1344ee']
[2025-01-29T23:45:11.700+0000] {standard_task_runner.py:88} INFO - Job 53: Subtask load_task
[2025-01-29T23:45:12.385+0000] {task_command.py:423} INFO - Running <TaskInstance: spotify_etl.load_task scheduled__2025-01-28T00:00:00+00:00 [running]> on host d9ce99263c32
[2025-01-29T23:45:14.485+0000] {taskinstance.py:2480} INFO - Exporting env vars: AIRFLOW_CTX_DAG_OWNER='***' AIRFLOW_CTX_DAG_ID='spotify_etl' AIRFLOW_CTX_TASK_ID='load_task' AIRFLOW_CTX_EXECUTION_DATE='2025-01-28T00:00:00+00:00' AIRFLOW_CTX_TRY_NUMBER='2' AIRFLOW_CTX_DAG_RUN_ID='scheduled__2025-01-28T00:00:00+00:00'
[2025-01-29T23:45:14.509+0000] {spotify_etl_dag.py:70} INFO - Starting load process...
[2025-01-29T23:45:14.518+0000] {warnings.py:109} WARNING - /home/***/.local/lib/python3.8/site-packages/***/utils/context.py:315: AirflowContextDeprecationWarning: Accessing 'execution_date' from the template is deprecated and will be removed in a future version. Please use 'data_interval_start' or 'logical_date' instead.
  warnings.warn(_create_deprecation_warning(k, replacements))

[2025-01-29T23:45:14.540+0000] {logging_mixin.py:188} INFO - Load task started at: 2025-01-28 00:00:00+00:00
[2025-01-29T23:45:14.778+0000] {logging_mixin.py:188} INFO - Retrieved 4 songs from XCom
[2025-01-29T23:45:14.780+0000] {logging_mixin.py:188} INFO - Retrieved 4 albums from XCom
[2025-01-29T23:45:14.858+0000] {base.py:83} INFO - Using connection ID 'mysql_connection' for task execution.
[2025-01-29T23:45:57.794+0000] {load.py:99} ERROR - Error loading data: (2002, "Can't connect to server on 'database-1.c1eo8uma67by.us-east-2.rds.amazonaws.com' (111)")
[2025-01-29T23:45:57.795+0000] {taskinstance.py:2698} ERROR - Task failed with exception
Traceback (most recent call last):
  File "/home/airflow/.local/lib/python3.8/site-packages/airflow/models/taskinstance.py", line 433, in _execute_task
    result = execute_callable(context=context, **execute_callable_kwargs)
  File "/home/airflow/.local/lib/python3.8/site-packages/airflow/operators/python.py", line 199, in execute
    return_value = self.execute_callable()
  File "/home/airflow/.local/lib/python3.8/site-packages/airflow/operators/python.py", line 216, in execute_callable
    return self.python_callable(*self.op_args, **self.op_kwargs)
  File "/opt/airflow/dags/spotify_etl_dag.py", line 82, in load
    load_to_staging(songs, albums)
  File "/opt/airflow/dags/etl/load.py", line 62, in load_to_staging
    create_schemas_if_not_exist(mysql_hook)
  File "/opt/airflow/dags/etl/load.py", line 10, in create_schemas_if_not_exist
    connection = mysql_hook.get_conn()
  File "/home/airflow/.local/lib/python3.8/site-packages/airflow/providers/mysql/hooks/mysql.py", line 195, in get_conn
    return MySQLdb.connect(**conn_config)
  File "/home/airflow/.local/lib/python3.8/site-packages/MySQLdb/__init__.py", line 121, in Connect
    return Connection(*args, **kwargs)
  File "/home/airflow/.local/lib/python3.8/site-packages/MySQLdb/connections.py", line 193, in __init__
    super().__init__(*args, **kwargs2)
MySQLdb.OperationalError: (2002, "Can't connect to server on 'database-1.c1eo8uma67by.us-east-2.rds.amazonaws.com' (111)")
[2025-01-29T23:45:57.929+0000] {taskinstance.py:1138} INFO - Marking task as FAILED. dag_id=spotify_etl, task_id=load_task, execution_date=20250128T000000, start_date=20250129T234511, end_date=20250129T234557
[2025-01-29T23:45:58.019+0000] {standard_task_runner.py:107} ERROR - Failed to execute job 53 for task load_task ((2002, "Can't connect to server on 'database-1.c1eo8uma67by.us-east-2.rds.amazonaws.com' (111)"); 188)
[2025-01-29T23:45:58.074+0000] {local_task_job_runner.py:234} INFO - Task exited with return code 1
[2025-01-29T23:45:58.119+0000] {taskinstance.py:3280} INFO - 0 downstream tasks scheduled from follow-on schedule check
